Workbook

Sheet total MM
A1: DATE | B1: SOLANA AVG PRICE | C1: IDLEMINE AVG PRICE | D1: BOUGHT TOKENS | E1: BOUGHT VOLUME | F1: SOLD TOKENS | G1: SOLD VOLUME | H1: TOTAL VOLUME | I1: TRANSACTION FEE | J1: POSTION TOKENS | K1: POSITION VALUE | L1: SOL IN | M1: SOL OUT | N1: NET SOL VALUE
A2: 45962 | B2: 222.076 | C2: 7.677e-06 | D2: ='MM volume and PL walletwise'!S3+'MM volume and PL walletwise'!#REF! -> #REF! | E2: ='MM volume and PL walletwise'!T3+'MM volume and PL walletwise'!#REF! -> #REF! | F2: ='MM volume and PL walletwise'!U3+'MM volume and PL walletwise'!#REF! -> #REF! | G2: ='MM volume and PL walletwise'!V3+'MM volume and PL walletwise'!#REF! -> #REF! | H2: ='MM volume and PL walletwise'!W3+'MM volume and PL walletwise'!#REF! -> #REF! | I2: ='MM volume and PL walletwise'!X3+'MM volume and PL walletwise'!#REF! -> #REF! | J2: ='MM volume and PL walletwise'!Y3+'MM volume and PL walletwise'!#REF! -> #REF! | K2: ='MM volume and PL walletwise'!Z3+'MM volume and PL walletwise'!#REF! -> #REF! | L2: ='MM volume and PL walletwise'!AA3+'MM volume and PL walletwise'!#REF! -> #REF! | M2: ='MM volume and PL walletwise'!AC3+'MM volume and PL walletwise'!#REF! -> #REF! | N2: ='MM volume and PL walletwise'!AE3+'MM volume and PL walletwise'!#REF! -> #REF!
A3: 45963 | B3: 234.695 | C3: 7.677e-06 | D3: ='MM volume and PL walletwise'!S4+'MM volume and PL walletwise'!#REF! -> #REF! | E3: ='MM volume and PL walletwise'!T4+'MM volume and PL walletwise'!#REF! -> #REF! | F3: ='MM volume and PL walletwise'!U4+'MM volume and PL walletwise'!#REF! -> #REF! | G3: ='MM volume and PL walletwise'!V4+'MM volume and PL walletwise'!#REF! -> #REF! | H3: ='MM volume and PL walletwise'!W4+'MM volume and PL walletwise'!#REF! -> #REF! | I3: ='MM volume and PL walletwise'!X4+'MM volume and PL walletwise'!#REF! -> #REF! | J3: ='MM volume and PL walletwise'!Y4+'MM volume and PL walletwise'!#REF! -> #REF! | K3: ='MM volume and PL walletwise'!Z4+'MM volume and PL walletwise'!#REF! -> #REF! | L3: ='MM volume and PL walletwise'!AA4+'MM volume and PL walletwise'!#REF! -> #REF! | M3: ='MM volume and PL walletwise'!AC4+'MM volume and PL walletwise'!#REF! -> #REF! | N3: ='MM volume and PL walletwise'!AE4+'MM volume and PL walletwise'!#REF! -> #REF!
A4: 45964 | B4: 232.82 | C4: 7.691e-06 | D4: ='MM volume and PL walletwise'!S5+'MM volume and PL walletwise'!#REF! -> #REF! | E4: ='MM volume and PL walletwise'!T5+'MM volume and PL walletwise'!#REF! -> #REF! | F4: ='MM volume and PL walletwise'!U5+'MM volume and PL walletwise'!#REF! -> #REF! | G4: ='MM volume and PL walletwise'!V5+'MM volume and PL walletwise'!#REF! -> #REF! | H4: ='MM volume and PL walletwise'!W5+'MM volume and PL walletwise'!#REF! -> #REF! | I4: ='MM volume and PL walletwise'!X5+'MM volume and PL walletwise'!#REF! -> #REF! | J4: ='MM volume and PL walletwise'!Y5+'MM volume and PL walletwise'!#REF! -> #REF! | K4: ='MM volume and PL walletwise'!Z5+'MM volume and PL walletwise'!#REF! -> #REF! | L4: ='MM volume and PL walletwise'!AA5+'MM volume and PL walletwise'!#REF! -> #REF! | M4: ='MM volume and PL walletwise'!AC5+'MM volume and PL walletwise'!#REF! -> #REF! | N4: ='MM volume and PL walletwise'!AE5+'MM volume and PL walletwise'!#REF! -> #REF!
A5: 45965 | B5: 227.925 | C5: 7.735e-06 | D5: ='MM volume and PL walletwise'!S6+'MM volume and PL walletwise'!#REF! -> #REF! | E5: ='MM volume and PL walletwise'!T6+'MM volume and PL walletwise'!#REF! -> #REF! | F5: ='MM volume and PL walletwise'!U6+'MM volume and PL walletwise'!#REF! -> #REF! | G5: ='MM volume and PL walletwise'!V6+'MM volume and PL walletwise'!#REF! -> #REF! | H5: ='MM volume and PL walletwise'!W6+'MM volume and PL walletwise'!#REF! -> #REF! | I5: ='MM volume and PL walletwise'!X6+'MM volume and PL walletwise'!#REF! -> #REF! | J5: ='MM volume and PL walletwise'!Y6+'MM volume and PL walletwise'!#REF! -> #REF! | K5: ='MM volume and PL walletwise'!Z6+'MM volume and PL walletwise'!#REF! -> #REF! | L5: ='MM volume and PL walletwise'!AA6+'MM volume and PL walletwise'!#REF! -> #REF! | M5: ='MM volume and PL walletwise'!AC6+'MM volume and PL walletwise'!#REF! -> #REF! | N5: ='MM volume and PL walletwise'!AE6+'MM volume and PL walletwise'!#REF! -> #REF!
A6: 45966 | B6: 228.559 | C6: 7.557e-06 | D6: ='MM volume and PL walletwise'!S7+'MM volume and PL walletwise'!#REF! -> #REF! | E6: ='MM volume and PL walletwise'!T7+'MM volume and PL walletwise'!#REF! -> #REF! | F6: ='MM volume and PL walletwise'!U7+'MM volume and PL walletwise'!#REF! -> #REF! | G6: ='MM volume and PL walletwise'!V7+'MM volume and PL walletwise'!#REF! -> #REF! | H6: ='MM volume and PL walletwise'!W7+'MM volume and PL walletwise'!#REF! -> #REF! | I6: ='MM volume and PL walletwise'!X7+'MM volume and PL walletwise'!#REF! -> #REF! | J6: ='MM volume and PL walletwise'!Y7+'MM volume and PL walletwise'!#REF! -> #REF! | K6: ='MM volume and PL walletwise'!Z7+'MM volume and PL walletwise'!#REF! -> #REF! | L6: ='MM volume and PL walletwise'!AA7+'MM volume and PL walletwise'!#REF! -> #REF! | M6: ='MM volume and PL walletwise'!AC7+'MM volume and PL walletwise'!#REF! -> #REF! | N6: ='MM volume and PL walletwise'!AE7+'MM volume and PL walletwise'!#REF! -> #REF!
A7: 45967 | B7: 230.603 | C7: 7.347e-06 | D7: ='MM volume and PL walletwise'!S8+'MM volume and PL walletwise'!#REF! -> #REF! | E7: ='MM volume and PL walletwise'!T8+'MM volume and PL walletwise'!#REF! -> #REF! | F7: ='MM volume and PL walletwise'!U8+'MM volume and PL walletwise'!#REF! -> #REF! | G7: ='MM volume and PL walletwise'!V8+'MM volume and PL walletwise'!#REF! -> #REF! | H7: ='MM volume and PL walletwise'!W8+'MM volume and PL walletwise'!#REF! -> #REF! | I7: ='MM volume and PL walletwise'!X8+'MM volume and PL walletwise'!#REF! -> #REF! | J7: ='MM volume and PL walletwise'!Y8+'MM volume and PL walletwise'!#REF! -> #REF! | K7: ='MM volume and PL walletwise'!Z8+'MM volume and PL walletwise'!#REF! -> #REF! | L7: ='MM volume and PL walletwise'!AA8+'MM volume and PL walletwise'!#REF! -> #REF! | M7: ='MM volume and PL walletwise'!AC8+'MM volume and PL walletwise'!#REF! -> #REF! | N7: ='MM volume and PL walletwise'!AE8+'MM volume and PL walletwise'!#REF! -> #REF!
A8: 45968 | B8: 231.267 | C8: 7.413e-06 | D8: ='MM volume and PL walletwise'!S9+'MM volume and PL walletwise'!#REF! -> #REF! | E8: ='MM volume and PL walletwise'!T9+'MM volume and PL walletwise'!#REF! -> #REF! | F8: ='MM volume and PL walletwise'!U9+'MM volume and PL walletwise'!#REF! -> #REF! | G8: ='MM volume and PL walletwise'!V9+'MM volume and PL walletwise'!#REF! -> #REF! | H8: ='MM volume and PL walletwise'!W9+'MM volume and PL walletwise'!#REF! -> #REF! | I8: ='MM volume and PL walletwise'!X9+'MM volume and PL walletwise'!#REF! -> #REF! | J8: ='MM volume and PL walletwise'!Y9+'MM volume and PL walletwise'!#REF! -> #REF! | K8: ='MM volume and PL walletwise'!Z9+'MM volume and PL walletwise'!#REF! -> #REF! | L8: ='MM volume and PL walletwise'!AA9+'MM volume and PL walletwise'!#REF! -> #REF! | M8: ='MM volume and PL walletwise'!AC9+'MM volume and PL walletwise'!#REF! -> #REF! | N8: ='MM volume and PL walletwise'!AE9+'MM volume and PL walletwise'!#REF! -> #REF!
A9: 45969 | B9: 229.012 | C9: 7.401e-06 | D9: ='MM volume and PL walletwise'!S10+'MM volume and PL walletwise'!#REF! -> #REF! | E9: ='MM volume and PL walletwise'!T10+'MM volume and PL walletwise'!#REF! -> #REF! | F9: ='MM volume and PL walletwise'!U10+'MM volume and PL walletwise'!#REF! -> #REF! | G9: ='MM volume and PL walletwise'!V10+'MM volume and PL walletwise'!#REF! -> #REF! | H9: ='MM volume and PL walletwise'!W10+'MM volume and PL walletwise'!#REF! -> #REF! | I9: ='MM volume and PL walletwise'!X10+'MM volume and PL walletwise'!#REF! -> #REF! | J9: ='MM volume and PL walletwise'!Y10+'MM volume and PL walletwise'!#REF! -> #REF! | K9: ='MM volume and PL walletwise'!Z10+'MM volume and PL walletwise'!#REF! -> #REF! | L9: ='MM volume and PL walletwise'!AA10+'MM volume and PL walletwise'!#REF! -> #REF! | M9: ='MM volume and PL walletwise'!AC10+'MM volume and PL walletwise'!#REF! -> #REF! | N9: ='MM volume and PL walletwise'!AE10+'MM volume and PL walletwise'!#REF! -> #REF!
A10: 45970 | B10: 220.949 | C10: 7.392e-06 | D10: ='MM volume and PL walletwise'!S11+'MM volume and PL walletwise'!#REF! -> #REF! | E10: ='MM volume and PL walletwise'!T11+'MM volume and PL walletwise'!#REF! -> #REF! | F10: ='MM volume and PL walletwise'!U11+'MM volume and PL walletwise'!#REF! -> #REF! | G10: ='MM volume and PL walletwise'!V11+'MM volume and PL walletwise'!#REF! -> #REF! | H10: ='MM volume and PL walletwise'!W11+'MM volume and PL walletwise'!#REF! -> #REF! | I10: ='MM volume and PL walletwise'!X11+'MM volume and PL walletwise'!#REF! -> #REF! | J10: ='MM volume and PL walletwise'!Y11+'MM volume and PL walletwise'!#REF! -> #REF! | K10: ='MM volume and PL walletwise'!Z11+'MM volume and PL walletwise'!#REF! -> #REF! | L10: ='MM volume and PL walletwise'!AA11+'MM volume and PL walletwise'!#REF! -> #REF! | M10: ='MM volume and PL walletwise'!AC11+'MM volume and PL walletwise'!#REF! -> #REF! | N10: ='MM volume and PL walletwise'!AE11+'MM volume and PL walletwise'!#REF! -> #REF!
A11: 45971 | B11: 218.576 | C11: 7.456e-06 | D11: ='MM volume and PL walletwise'!S12+'MM volume and PL walletwise'!#REF! -> #REF! | E11: ='MM volume and PL walletwise'!T12+'MM volume and PL walletwise'!#REF! -> #REF! | F11: ='MM volume and PL walletwise'!U12+'MM volume and PL walletwise'!#REF! -> #REF! | G11: ='MM volume and PL walletwise'!V12+'MM volume and PL walletwise'!#REF! -> #REF! | H11: ='MM volume and PL walletwise'!W12+'MM volume and PL walletwise'!#REF! -> #REF! | I11: ='MM volume and PL walletwise'!X12+'MM volume and PL walletwise'!#REF! -> #REF! | J11: ='MM volume and PL walletwise'!Y12+'MM volume and PL walletwise'!#REF! -> #REF! | K11: ='MM volume and PL walletwise'!Z12+'MM volume and PL walletwise'!#REF! -> #REF! | L11: ='MM volume and PL walletwise'!AA12+'MM volume and PL walletwise'!#REF! -> #REF! | M11: ='MM volume and PL walletwise'!AC12+'MM volume and PL walletwise'!#REF! -> #REF! | N11: ='MM volume and PL walletwise'!AE12+'MM volume and PL walletwise'!#REF! -> #REF!
A12: 45972 | B12: 183.425 | C12: 7.517e-06 | D12: ='MM volume and PL walletwise'!S13+'MM volume and PL walletwise'!#REF! -> #REF! | E12: ='MM volume and PL walletwise'!T13+'MM volume and PL walletwise'!#REF! -> #REF! | F12: ='MM volume and PL walletwise'!U13+'MM volume and PL walletwise'!#REF! -> #REF! | G12: ='MM volume and PL walletwise'!V13+'MM volume and PL walletwise'!#REF! -> #REF! | H12: ='MM volume and PL walletwise'!W13+'MM volume and PL walletwise'!#REF! -> #REF! | I12: ='MM volume and PL walletwise'!X13+'MM volume and PL walletwise'!#REF! -> #REF! | J12: ='MM volume and PL walletwise'!Y13+'MM volume and PL walletwise'!#REF! -> #REF! | K12: ='MM volume and PL walletwise'!Z13+'MM volume and PL walletwise'!#REF! -> #REF! | L12: ='MM volume and PL walletwise'!AA13+'MM volume and PL walletwise'!#REF! -> #REF! | M12: ='MM volume and PL walletwise'!AC13+'MM volume and PL walletwise'!#REF! -> #REF! | N12: ='MM volume and PL walletwise'!AE13+'MM volume and PL walletwise'!#REF! -> #REF!
A13: 45973 | B13: 197.244 | C13: 7.569e-06 | D13: ='MM volume and PL walletwise'!S14+'MM volume and PL walletwise'!#REF! -> #REF! | E13: ='MM volume and PL walletwise'!T14+'MM volume and PL walletwise'!#REF! -> #REF! | F13: ='MM volume and PL walletwise'!U14+'MM volume and PL walletwise'!#REF! -> #REF! | G13: ='MM volume and PL walletwise'!V14+'MM volume and PL walletwise'!#REF! -> #REF! | H13: ='MM volume and PL walletwise'!W14+'MM volume and PL walletwise'!#REF! -> #REF! | I13: ='MM volume and PL walletwise'!X14+'MM volume and PL walletwise'!#REF! -> #REF! | J13: ='MM volume and PL walletwise'!Y14+'MM volume and PL walletwise'!#REF! -> #REF! | K13: ='MM volume and PL walletwise'!Z14+'MM volume and PL walletwise'!#REF! -> #REF! | L13: ='MM volume and PL walletwise'!AA14+'MM volume and PL walletwise'!#REF! -> #REF! | M13: ='MM volume and PL walletwise'!AC14+'MM volume and PL walletwise'!#REF! -> #REF! | N13: ='MM volume and PL walletwise'!AE14+'MM volume and PL walletwise'!#REF! -> #REF!
... A29: 45989 | B29: 203.249 | C29: 8.924e-06 | D29: ='MM volume and PL walletwise'!S30+'MM volume and PL walletwise'!#REF! -> #REF! | E29: ='MM volume and PL walletwise'!T30+'MM volume and PL walletwise'!#REF! -> #REF! | F29: ='MM volume and PL walletwise'!U30+'MM volume and PL walletwise'!#REF! -> #REF! | G29: ='MM volume and PL walletwise'!V30+'MM volume and PL walletwise'!#REF! -> #REF! | H29: ='MM volume and PL walletwise'!W30+'MM volume and PL walletwise'!#REF! -> #REF! | I29: ='MM volume and PL walletwise'!X30+'MM volume and PL walletwise'!#REF! -> #REF! | J29: ='MM volume and PL walletwise'!Y30+'MM volume and PL walletwise'!#REF! -> #REF! | K29: ='MM volume and PL walletwise'!Z30+'MM volume and PL walletwise'!#REF! -> #REF! | L29: ='MM volume and PL walletwise'!AA30+'MM volume and PL walletwise'!#REF! -> #REF! | M29: ='MM volume and PL walletwise'!AC30+'MM volume and PL walletwise'!#REF! -> #REF! | N29: ='MM volume and PL walletwise'!AE30+'MM volume and PL walletwise'!#REF! -> #REF!
A30: 45990 | B30: 195.357 | C30: 9.085e-06 | D30: ='MM volume and PL walletwise'!#REF!+'MM volume and PL walletwise'!#REF! -> #REF! | E30: ='MM volume and PL walletwise'!#REF!+'MM volume and PL walletwise'!#REF! -> #REF! | F30: ='MM volume and PL walletwise'!#REF!+'MM volume and PL walletwise'!#REF! -> #REF! | G30: ='MM volume and PL walletwise'!#REF!+'MM volume and PL walletwise'!#REF! -> #REF! | H30: ='MM volume and PL walletwise'!#REF!+'MM volume and PL walletwise'!#REF! -> #REF! | I30: ='MM volume and PL walletwise'!#REF!+'MM volume and PL walletwise'!#REF! -> #REF! | J30: ='MM volume and PL walletwise'!#REF!+'MM volume and PL walletwise'!#REF! -> #REF! | K30: ='MM volume and PL walletwise'!#REF!+'MM volume and PL walletwise'!#REF! -> #REF! | ... N30: ='MM volume and PL walletwise'!#REF!+'MM volume and PL walletwise'!#REF! -> #REF!
A31: 45991 | B31: 190.998 | C31: 9.048e-06 | D31: ='MM volume and PL walletwise'!#REF!+'MM volume and PL walletwise'!#REF! -> #REF! | E31: ='MM volume and PL walletwise'!#REF!+'MM volume and PL walletwise'!#REF! -> #REF! | F31: ='MM volume and PL walletwise'!#REF!+'MM volume and PL walletwise'!#REF! -> #REF! | G31: ='MM volume and PL walletwise'!#REF!+'MM volume and PL walletwise'!#REF! -> #REF! | H31: ='MM volume and PL walletwise'!#REF!+'MM volume and PL walletwise'!#REF! -> #REF! | I31: ='MM volume and PL walletwise'!#REF!+'MM volume and PL walletwise'!#REF! -> #REF! | J31: ='MM volume and PL walletwise'!#REF!+'MM volume and PL walletwise'!#REF! -> #REF! | K31: ='MM volume and PL walletwise'!#REF!+'MM volume and PL walletwise'!#REF! -> #REF! | ... N31: ='MM volume and PL walletwise'!#REF!+'MM volume and PL walletwise'!#REF! -> #REF!

Sheet MM volume and PL walletwise
R1: RWA TOKEN COINX W1: 9N2gWYrNkbDCekkjA3NzgPuKrBz4dtHJFd4by6pdPhtM | AG1: RWA TOKEN COINX W2: E58mYFPjZJTcofQ6SDvjFC6Gse7fP8HzMbYoHAcWzFVM | AV1: RWA TOKEN HOODX W1: 5p7Ng6yMxXJpUV88zmkn7tscfHXGfwmvjnNyvfs7EeM1 | BK1: RWA TOKEN HOODX W2: HNtq33qLPmg1WuVTDVnKNpGBF4WpKHYudokySaokLbkT | BZ1: RWA TOKEN NVADA W1: F7hRiHqiKLnLy4Ac8MqL25j3BjY6zFsmgyexDs68CJLd | CO1: RWA TOKEN NVADA W2: GiucUuNCVJjwUHoKou6vkub8sGwJ87Vn2TbgUCPKysih | DD1: RWA TOKEN GOLDX W1: Em86CXDqv3zgJ5LSVk9R7qiTjnjs3SMnnpRoZ1Qf22Up | DS1: RWA TOKEN GOLDX W2: BPRXLpfwu5t8msAimCTxS1YCio11SFRPkRC3QquATwR1 | EH1: RWA TOKEN TESLA W1: 5DcA9dXb8ui3q4WJX5erp7niZrEwZmvtp631RQ79hcHd | EW1: RWA TOKEN TESLA W2: 9iBv3p4PoVq9z5sfew8X6MshESjbz4eKbTKmZwde9wem | FL1: RWA TOKEN PUMP W1: 297uWXCxwsZ2chYqe1RnQrWJYwpqddhsepdkCqV61MJU | GA1: RWA TOKEN PUMP W2: Cgj5KsSuMWUoKz4vrfshbdregoRmWvzALK7nzsCgbiQn | GP1: RWA TOKEN TRUMPX W1: FY4yaWTEoNjwFf2ZT8f69HJYVV4EXVgcQZr1caQCKywx | HE1: RWA TOKEN TRUMPX W2: BxezKiMMjoP9FuvHFWCzcsieEb9CZMDHDtoBcBPvSvXJ | HT1: RWA TOKEN QQQX W1: 9mnYf2EHLK9o57gQGdTHK6nUG1iZ213GaeKHJMjZTEMK | II1: RWA TOKEN QQQX W2: CotcqVgrV1jkBbmp8ZwSVQFp6Jazt3KdhN77ryvBipts | IX1: RWA TOKEN MSTRX W1: GE6QXG4b2RcKC2w1H8pqt38dYpABHJHKBNqkvrd92dHn | JM1: RWA TOKEN MSTRX W2: 5ApumhYiTozrA5P17SUZt567tUtDy4rbwoujc2fkBWDk | KB1: RWA TOKEN SPYRIDLE W1: Ey64tdGjU77HQhM85SmCWgA5AaPZuxFusWNnHD3kzhh8 | KQ1: RWA TOKEN SPYRIDLE W2: AeppnyrZ6t9EdzLoRzjWqdFRjQdDjVWFxCq5kAba2AzE | LF1: RWA TOKEN CRCLXIDLE W1: 8HWaTRUfnWdzcVxzHihunrN52nivLe7x3QXNA9Lhw3HE | LU1: RWA TOKEN CRCLXIDLE W2: E2rqXqTo68ALfDw9QoV5Qg55qgS9FeoZwpTS4AqT4yXL | MJ1: RWA TOKEN GOOGLXIDLE W1: Giu5jpTs23wodEgNwKeWRY689gBXc1ZwkpT2nf3qnLqt | MY1: RWA TOKEN GOOGLXIDLE W2: 9nXk7f58tRXLuNwRjuY5pFjegTtuvmfr8EsNzWWkhJd8 | NN1: RWA TOKEN PENGUIDLE W1: EsD4rJ6Dhhz7vSv98kKS49sUVMabcBhBRHYShhL7CPbb | OC1: RWA TOKEN PENGUIDLE W2: AoYwXgDU9PDiKnFu1vJBma1wDERQYBfJzTRjZeiaVZcj
A2: DATE | B2: COINX AVG PRICE | C2: HOODX AVG PRICE | D2: NVADAX AVG PRICE | E2: GOLDX AVG PRICE | F2: TESLAX AVG PRICE | G2: PUMP AVG PRICE | H2: TRUMP AVG PRICE | I2: QQQX AVG PRICE | J2: MSTRX AVG PRICE | K2: SPYRIDLE AVG PRICE | L2: CRCLXIDLE AVG PRICE | M2: GOOGLXIDLE AVG PRICE | N2: PENGUIDLE AVG PRICE | O2: SOLONA AVG PRICE | P2: IDLEMINE AVG PRICE | R2: DATE | S2: BOUGHT TOKENS | T2: BOUGHT VOLUME | U2: SOLD TOKENS | V2: SOLD VOLUME | W2: TOTAL VOLUME | X2: TRANSACTION FEE | Y2: POSTION TOKENS | Z2: POSITION VALUE | AA2: COINX IN | AB2: COINX IN VALUE | AC2: COINX OUT | AD2: COINX OUT VALUE | AE2: NET TOKEN VALUE | AG2: DATE | AH2: BOUGHT TOKENS | AI2: BOUGHT VOLUME | AJ2: SOLD TOKENS | AK2: SOLD VOLUME | AL2: TOTAL VOLUME | AM2: TRANSACTION FEE | AN2: POSTION TOKENS | AO2: POSITION VALUE | AP2: COINX IN | AQ2: COINX IN VALUE | AR2: COINX OUT | AS2: COINX OUT VALUE | AT2: NET TOKEN. VALUE | AV2: DATE | AW2: BOUGHT TOKENS | AX2: BOUGHT VOLUME | AY2: SOLD TOKENS | AZ2: SOLD VOLUME | BA2: TOTAL VOLUME | BB2: TRANSACTION FEE | BC2: POSTION TOKENS | BD2: POSITION VALUE | BE2: HOODX IN | BF2: HOODX IN VALUE | BG2: HOODX OUT | BH2: HOODX OUT VALUE | BI2: NET TOKEN. VALUE | BK2: DATE | BL2: BOUGHT TOKENS | BM2: BOUGHT VOLUME | BN2: SOLD TOKENS | BO2: SOLD VOLUME | BP2: TOTAL VOLUME | BQ2: TRANSACTION FEE | BR2: POSTION TOKENS | BS2: POSITION VALUE | BT2: HOODX IN | BU2: HOODX IN VALUE | BV2: HOODX OUT | BW2: HOODX OUT VALUE | BX2: NET TOKEN VALUE | BZ2: DATE | CA2: BOUGHT TOKENS | CB2: BOUGHT VOLUME | CC2: SOLD TOKENS | CD2: SOLD VOLUME | CE2: TOTAL VOLUME | CF2: TRANSACTION FEE | CG2: POSTION TOKENS | CH2: POSITION VALUE | CI2: NVADA IN | CJ2: NVADA IN VALUE | CK2: NVADA OUT | CL2: NVADA OUT VALUE | CM2: NET TOKEN VALUE | CO2: DATE | CP2: BOUGHT TOKENS | CQ2: BOUGHT VOLUME | CR2: SOLD TOKENS | CS2: SOLD VOLUME | CT2: TOTAL VOLUME | CU2: TRANSACTION FEE | CV2: POSTION TOKENS | CW2: POSITION VALUE | CX2: NVADA IN | CY2: NVADA IN VALUE | CZ2: NVADA OUT | DA2: NVADA OUT VALUE | DB2: NET TOKEN VALUE | DD2: DATE | DE2: BOUGHT TOKENS | DF2: BOUGHT VOLUME | DG2: SOLD TOKENS | DH2: SOLD VOLUME | DI2: TOTAL VOLUME | DJ2: TRANSACTION FEE | DK2: POSTION TOKENS | DL2: POSITION VALUE | DM2: GOLDX IN | DN2: GOLDX IN VALUE | DO2: GOLDX OUT | DP2: GOLDX OUT VALUE | DQ2: NET TOKEN VALUE | DS2: DATE | DT2: BOUGHT TOKENS | DU2: BOUGHT VOLUME | DV2: SOLD TOKENS | DW2: SOLD VOLUME | DX2: TOTAL VOLUME | DY2: TRANSACTION FEE | DZ2: POSTION TOKENS | EA2: POSITION VALUE | EB2: GOLDX IN | EC2: GOLDX IN VALUE | ED2: GOLDX OUT | EE2: GOLDXX OUT VALUE | EF2: NET TOKEN VALUE | EH2: DATE | EI2: BOUGHT TOKENS | EJ2: BOUGHT VOLUME | EK2: SOLD TOKENS | EL2: SOLD VOLUME | EM2: TOTAL VOLUME | EN2: TRANSACTION FEE | EO2: POSTION TOKENS | EP2: POSITION VALUE | EQ2: TESLA IN | ER2: TESLA IN VALUE | ES2: TESLA OUT | ET2: TESLA OUT VALUE | EU2: NET TOKEN VALUE | EW2: DATE | EX2: BOUGHT TOKENS | EY2: BOUGHT VOLUME | EZ2: SOLD TOKENS | FA2: SOLD VOLUME | FB2: TOTAL VOLUME | FC2: TRANSACTION FEE | FD2: POSTION TOKENS | FE2: POSITION VALUE | FF2: TESLA IN | FG2: TESLA IN VALUE | FH2: TESLA OUT | FI2: TESLA OUT VALUE | FJ2: NET TOKEN VALUE | FL2: DATE | FM2: BOUGHT TOKENS | FN2: BOUGHT VOLUME | FO2: SOLD TOKENS | FP2: SOLD VOLUME | FQ2: TOTAL VOLUME | FR2: TRANSACTION FEE | FS2: POSTION TOKENS | FT2: POSITION VALUE | FU2: PUMPX IN | FV2: PUMPX IN VALUE | FW2: PUMPX OUT | FX2: PUMPX OUT VALUE | FY2: NET TOKEN VALUE | GA2: DATE | GB2: BOUGHT TOKENS | GC2: BOUGHT VOLUME | GD2: SOLD TOKENS | GE2: SOLD VOLUME | GF2: TOTAL VOLUME | GG2: TRANSACTION FEE | GH2: POSTION TOKENS | GI2: POSITION VALUE | GJ2: PUMPX IN | GK2: PUMPX IN VALUE | GL2: PUMPX OUT | GM2: PUMPX OUT VALUE | GN2: NET TOKEN VALUE | GP2: DATE | GQ2: BOUGHT TOKENS | GR2: BOUGHT VOLUME | GS2: SOLD TOKENS | GT2: SOLD VOLUME | GU2: TOTAL VOLUME | GV2: TRANSACTION FEE | GW2: POSTION TOKENS | GX2: POSITION VALUE | GY2: TRUMP IN | GZ2: TRUMP IN VALUE | HA2: TRUMP OUT | HB2: TRUMP OUT VALUE | HC2: NET TOKEN VALUE | HE2: DATE | HF2: BOUGHT TOKENS | HG2: BOUGHT VOLUME | HH2: SOLD TOKENS | HI2: SOLD VOLUME | HJ2: TOTAL VOLUME | HK2: TRANSACTION FEE | HL2: POSTION TOKENS | HM2: POSITION VALUE | HN2: TRUMP IN | HO2: TRUMP IN VALUE | HP2: TRUMP OUT | HQ2: TRUMP OUT VALUE | HR2: NET TOKEN VALUE | HT2: DATE | HU2: BOUGHT TOKENS | HV2: BOUGHT VOLUME | HW2: SOLD TOKENS | HX2: SOLD VOLUME | HY2: TOTAL VOLUME | HZ2: TRANSACTION FEE | IA2: POSTION TOKENS | IB2: POSITION VALUE | IC2: QQQX IN | ID2: QQQX IN VALUE | IE2: QQQX OUT | IF2: QQQX OUT VALUE | IG2: NET TOKEN VALUE | II2: DATE | IJ2: BOUGHT TOKENS | IK2: BOUGHT VOLUME | IL2: SOLD TOKENS | IM2: SOLD VOLUME | IN2: TOTAL VOLUME | IO2: TRANSACTION FEE | IP2: POSTION TOKENS | IQ2: POSITION VALUE | IR2: QQQX IN | IS2: QQQX IN VALUE | IT2: QQQX OUT | IU2: QQQX OUT VALUE | IV2: NET TOKEN VALUE | IX2: DATE | IY2: BOUGHT TOKENS | IZ2: BOUGHT VOLUME | JA2: SOLD TOKENS | JB2: SOLD VOLUME | JC2: TOTAL VOLUME | JD2: TRANSACTION FEE | JE2: POSTION TOKENS | JF2: POSITION VALUE | JG2: MSTRX IN | JH2: MSTRX IN VALUE | JI2: MSTRX OUT | JJ2: MSTRX OUT VALUE | JK2: NET TOKEN VALUE | JM2: DATE | JN2: BOUGHT TOKENS | JO2: BOUGHT VOLUME | JP2: SOLD TOKENS | JQ2: SOLD VOLUME | JR2: TOTAL VOLUME | JS2: TRANSACTION FEE | JT2: POSTION TOKENS | JU2: POSITION VALUE | JV2: MSTRX IN | JW2: MSTRX IN VALUE | JX2: MSTRX OUT | JY2: MSTRX OUT VALUE | JZ2: NET TOKEN VALUE | KB2: DATE | KC2: BOUGHT TOKENS | KD2: BOUGHT VOLUME | KE2: SOLD TOKENS | KF2: SOLD VOLUME | KG2: TOTAL VOLUME | KH2: TRANSACTION FEE | KI2: POSTION TOKENS | KJ2: POSITION VALUE | KK2: SPYRIDLE IN | KL2: SPYRIDLE IN VALUE | KM2: SPYRIDLE OUT | KN2: SPYRIDLE OUT VALUE | KO2: NET TOKEN VALUE | KQ2: DATE | KR2: BOUGHT TOKENS | KS2: BOUGHT VOLUME | KT2: SOLD TOKENS | KU2: SOLD VOLUME | KV2: TOTAL VOLUME | KW2: TRANSACTION FEE | KX2: POSTION TOKENS | KY2: POSITION VALUE | KZ2: SPYRIDLE IN | LA2: SPYRIDLE IN VALUE | LB2: SPYRIDLE OUT | LC2: SPYRIDLE OUT VALUE | LD2: NET TOKEN VALUE | LF2: DATE | LG2: BOUGHT TOKENS | LH2: BOUGHT VOLUME | LI2: SOLD TOKENS | LJ2: SOLD VOLUME | LK2: TOTAL VOLUME | LL2: TRANSACTION FEE | LM2: POSTION TOKENS | LN2: POSITION VALUE | LO2: CRCLXIDLE IN | LP2: CRCLIDLE IN VALUE | LQ2: CRCLXIDLE OUT | LR2: CRCLXIDLE OUT VALUE | LS2: NET TOKEN VALUE | LU2: DATE | LV2: BOUGHT TOKENS | LW2: BOUGHT VOLUME | LX2: SOLD TOKENS | LY2: SOLD VOLUME | LZ2: TOTAL VOLUME | MA2: TRANSACTION FEE | MB2: POSTION TOKENS | MC2: POSITION VALUE | MD2: CRCLXIDLE IN | ME2: CRCLXIDLE IN VALUE | MF2: CRCLXIDLE OUT | MG2: CRCLXIDLE OUT VALUE | MH2: NET TOKEN VALUE | MJ2: DATE | MK2: BOUGHT TOKENS | ML2: BOUGHT VOLUME | MM2: SOLD TOKENS | MN2: SOLD VOLUME | MO2: TOTAL VOLUME | MP2: TRANSACTION FEE | MQ2: POSTION TOKENS | MR2: POSITION VALUE | MS2: GOOGLXIDLE IN | MT2: GOOGLXIDLE IN VALUE | MU2: GOOGLXIDLE OUT | MV2: GOOGLXIDLE OUT VALUE | MW2: NET TOKEN VALUE | MY2: DATE | MZ2: BOUGHT TOKENS | NA2: BOUGHT VOLUME | NB2: SOLD TOKENS | NC2: SOLD VOLUME | ND2: TOTAL VOLUME | NE2: TRANSACTION FEE | NF2: POSTION TOKENS | NG2: POSITION VALUE | NH2: GOOGLXIDE IN | NI2: GOOGLXIDLE IN VALUE | NJ2: GOOGLXIDLE OUT | NK2: GOOGLXIDLE OUT VALUE | NL2: NET TOKEN VALUE | NN2: DATE | NO2: BOUGHT TOKENS | NP2: BOUGHT VOLUME | NQ2: SOLD TOKENS | NR2: SOLD VOLUME | NS2: TOTAL VOLUME | NT2: TRANSACTION FEE | NU2: POSTION TOKENS | NV2: POSITION VALUE | NW2: PENGUIDLE IN | NX2: PENGUIDLE IN VALUE | NY2: PENGUIDLE OUT | NZ2: PENGUIDLE OUT VALUE | OA2: NET TOKEN VALUE | OC2: DATE | OD2: BOUGHT TOKENS | OE2: BOUGHT VOLUME | OF2: SOLD TOKENS | OG2: SOLD VOLUME | OH2: TOTAL VOLUME | OI2: TRANSACTION FEE | OJ2: POSTION TOKENS | OK2: POSITION VALUE | OL2: PENGUIDLE IN | OM2: PENGUIDLE IN VALUE | ON2: PENGUIDLE OUT | OO2: PENGUIDLE OUT VALUE | OP2: NET TOKEN VALUE
A3: 46054 | B3: 188.56 | C3: 98.61 | D3: 188.6 | E3: 449.93 | F3: 425.77 | G3: 0.00256 | H3: 4.139 | I3: 621.16 | J3: 134.69 | K3: 695.49 | L3: 61.79 | M3: 335.38 | N3: 0.00753 | O3: 105.054 | P3: 2.918e-05 | R3: 46054 | S3: 841554.52 | T3: =S3*P3*O3 -> 2579.765 | U3: 842801.98 | V3: =U3*P3*O3 -> 2583.589 | W3: =T3+V3 -> 5163.354 | Y3: =S3-U3 -> -1247.4589 | Z3: =Y3*P3*O3 -> -3.824055 | AA3: 13.492004 | AB3: =AA3*B3 -> 2544.0522 | AC3: 13.743678 | AD3: =AC3*B3 -> 2591.5079 | AE3: =(AA3-AC3)*B3 -> -47.455732 | AG3: 46054 | AH3: 801725.94 | AI3: =AH3*P3*O3 -> 2457.6714 | AJ3: 822310.13 | AK3: =AJ3*P3*O3 -> 2520.7717 | AL3: =AI3+AK3 -> 4978.4431 | AN3: =AH3-AJ3 -> -20584.196 | AO3: =AN3*P3*O3 -> -63.100354 | AP3: 13.159427 | AQ3: =AP3*B3 -> 2481.3415 | AR3: 13.093303 | AS3: =AR3*B3 -> 2468.8731 | AT3: =(AP3-AR3)*B3 -> 12.468357 | AV3: 46054 | AW3: 814528.07 | AX3: =AW3*P3*O3 -> 2496.916 | AY3: 839429.38 | AZ3: =AY3*P3*O3 -> 2573.2504 | BA3: =AX3+AZ3 -> 5070.1664 | BC3: =AW3-AY3 -> -24901.316 | BD3: =BC3*P3*O3 -> -76.334379 | BE3: 25.665842 | BF3: =BE3*C3 -> 2530.9086 | BG3: 25.408933 | BH3: =BG3*C3 -> 2505.5749 | BI3: =(BE3-BG3)*C3 -> 25.333769 | BK3: 46054 | BL3: 771274.83 | BM3: =BL3*P3*O3 -> 2364.3243 | BN3: 786440.72 | BO3: =BN3*P3*O3 -> 2410.8149 | BP3: =BM3+BO3 -> 4775.1392 | BR3: =BL3-BN3 -> -15165.885 | BS3: =BR3*P3*O3 -> -46.490653 | BT3: 24.043968 | BU3: =BT3*C3 -> 2370.9757 | BV3: 24.062598 | BW3: =BV3*C3 -> 2372.8128 | BX3: =(BT3-BV3)*C3 -> -1.8370451 | BZ3: 46054 | CA3: 820152.52 | CB3: =CA3*P3*O3 -> 2514.1576 | CC3: 826254.03 | CD3: =CC3*P3*O3 -> 2532.8617 | CE3: =CB3+CD3 -> 5047.0193 | CG3: =CA3-CC3 -> -6101.5085 | CH3: =CG3*P3*O3 -> -18.704026 | CI3: 13.208321 | CJ3: =CI3*D3 -> 2491.0894 | CK3: 13.37928 | CL3: =CK3*D3 -> 2523.3323 | CM3: =(CI3-CK3)*D3 -> -32.24289 | CO3: 46054 | CP3: 822968.18 | CQ3: =CP3*P3*O3 -> 2522.789 | CR3: 841394.69 | CS3: =CR3*P3*O3 -> 2579.275 | CT3: =CQ3+CS3 -> 5102.0639 | CV3: =CP3-CR3 -> -18426.509 | CW3: =CV3*P3*O3 -> -56.486017 | CX3: 13.451798 | CY3: =CX3*D3 -> 2537.009 | CZ3: 13.426632 | DA3: =CZ3*D3 -> 2532.2628 | DB3: =(CX3-CZ3)*D3 -> 4.7462227 | DD3: 46054 | DE3: 836753.88 | DF3: =DE3*P3*O3 -> 2565.0487 | DG3: 845718.84 | DH3: =DG3*P3*O3 -> 2592.5306 | DI3: =DF3+DH3 -> 5157.5793 | DK3: =DE3-DG3 -> -8964.9669 | DL3: =DK3*P3*O3 -> -27.481888 | DM3: 5.6892393 | DN3: =DM3*E3 -> 2559.7594 | DO3: 5.7438477 | DP3: =DO3*E3 -> 2584.3294 | DQ3: =(DM3-DO3)*E3 -> -24.569962 | DS3: 46054 | DT3: 822282.75 | DU3: =DT3*P3*O3 -> 2520.6878 | DV3: 842663.29 | DW3: =DV3*P3*O3 -> 2583.1639 | DX3: =DU3+DW3 -> 5103.8516 | DZ3: =DT3-DV3 -> -20380.544 | EA3: =DZ3*P3*O3 -> -62.476063 | EB3: 5.6687764 | EC3: =EB3*E3 -> 2550.5526 | ED3: 5.6455877 | EE3: =ED3*E3 -> 2540.1193 | EF3: =(EB3-ED3)*E3 -> 10.433323 | EH3: 46054 | EI3: 2338214 | EJ3: =EI3*P3*O3 -> 7167.7382 | EK3: 2385035 | EL3: =EK3*P3*O3 -> 7311.2669 | EM3: =EJ3+EL3 -> 14479.005 | EO3: =EI3-EK3 -> -46821 | EP3: =EO3*P3*O3 -> -143.52864 | EQ3: 16.97736 | ER3: =EQ3*F3 -> 7228.4506 | ES3: 16.72719 | ET3: =ES3*F3 -> 7121.9357 | EU3: =(EQ3-ES3)*F3 -> 106.51488 | EW3: 46054 | EX3: 2222785 | EY3: =EX3*P3*O3 -> 6813.8934 | EZ3: 2238490 | FA3: =EZ3*P3*O3 -> 6862.0367 | FB3: =EY3+FA3 -> 13675.93 | FD3: =EX3-EZ3 -> -15705 | FE3: =FD3*P3*O3 -> -48.143296 | FF3: 15.92422 | FG3: =FF3*F3 -> 6780.0551 | FH3: 15.90518 | FI3: =FH3*F3 -> 6771.9485 | FJ3: =(FF3-FH3)*F3 -> 8.1066608 | FL3: 46054 | FM3: 639626.5 | FN3: =FM3*P3*O3 -> 1960.7595 | FO3: 614210.5 | FP3: =FO3*P3*O3 -> 1882.8474 | FQ3: =FN3+FP3 -> 3843.6069 | FS3: =FM3-FO3 -> 25416 | FT3: =FS3*P3*O3 -> 77.912131 | FU3: 699754.5 | FV3: =FU3*G3 -> 1791.3715 | FW3: 759130.4 | FX3: =FW3*G3 -> 1943.3738 | FY3: =(FU3-FW3)*G3 -> -152.0023 | GA3: 46054 | GB3: 626233.6 | GC3: =GB3*P3*O3 -> 1919.7039 | GD3: 613254 | GE3: =GD3*P3*O3 -> 1879.9152 | GF3: =GC3+GE3 -> 3799.6191 | GH3: =GB3-GD3 -> 12979.6 | GI3: =GH3*P3*O3 -> 39.788649 | GJ3: 698789.1 | GK3: =GJ3*G3 -> 1788.9001 | GL3: 743332.6 | GM3: =GL3*G3 -> 1902.9315 | GN3: =(GJ3-GL3)*G3 -> -114.03136 | GP3: 46054 | GQ3: 644692.9 | GR3: =GQ3*P3*O3 -> 1976.2904 | GS3: 630705.4 | GT3: =GS3*P3*O3 -> 1933.4121 | GU3: =GR3+GT3 -> 3909.7025 | GW3: =GQ3-GS3 -> 13987.5 | GX3: =GW3*P3*O3 -> 42.878342 | GY3: 443.9147 | GZ3: =GY3*H3 -> 1837.3629 | HA3: 472.4171 | HB3: =HA3*H3 -> 1955.3344 | HC3: =(GY3-HA3)*H3 -> -117.97143 | HE3: 46054 | HF3: 640135.3 | HG3: =HF3*P3*O3 -> 1962.3192 | HH3: 618652.8 | HI3: =HH3*P3*O3 -> 1896.4651 | HJ3: =HG3+HI3 -> 3858.7844 | HL3: =HF3-HH3 -> 21482.5 | HM3: =HL3*P3*O3 -> 65.854082 | HN3: 435.2707 | HO3: =HN3*H3 -> 1801.5854 | HP3: 469.1121 | HQ3: =HP3*H3 -> 1941.655 | HR3: =(HN3-HP3)*H3 -> -140.06955 | HT3: 46054 | HV3: =HU3*P3*O3 -> 0 | HX3: =HW3*P3*O3 -> 0 | HY3: =HV3+HX3 -> 0 | IA3: =HU3-HW3 -> 0 | IB3: =IA3*P3*O3 -> 0 | ID3: =IC3*I3 -> 0 | IF3: =IE3*I3 -> 0 | IG3: =(IC3-IE3)*I3 -> 0 | II3: 46054 | IK3: =IJ3*P3*O3 -> 0 | IM3: =IL3*P3*O3 -> 0 | IN3: =IK3+IM3 -> 0 | IP3: =IJ3-IL3 -> 0 | IQ3: =IP3*P3*O3 -> 0 | IS3: =IR3*I3 -> 0 | IU3: =IT3*I3 -> 0 | IV3: =(IR3-IT3)*I3 -> 0 | IX3: 46054 | IY3: 834131.6 | IZ3: =IY3*P3*O3 -> 2557.0102 | JA3: 836562.9 | JB3: =JA3*P3*O3 -> 2564.4633 | JC3: =IZ3+JB3 -> 5121.4734 | JE3: =IY3-JA3 -> -2431.3 | JF3: =JE3*P3*O3 -> -7.4530911 | JG3: 18.18262 | JH3: =JG3*J3 -> 2449.0171 | JI3: 18.49033 | JJ3: =JI3*J3 -> 2490.4625 | JK3: =(JG3-JI3)*J3 -> -41.44546 | JM3: 46054 | JN3: 809606.8 | JO3: =JN3*P3*O3 -> 2481.83 | JP3: 813071.7 | JQ3: =JP3*P3*O3 -> 2492.4516 | JR3: =JO3+JQ3 -> 4974.2815 | JT3: =JN3-JP3 -> -3464.9 | JU3: =JT3*P3*O3 -> -10.621567 | JV3: 17.66473 | JW3: =JV3*J3 -> 2379.2625 | JX3: 17.96052 | JY3: =JX3*J3 -> 2419.1024 | JZ3: =(JV3-JX3)*J3 -> -39.839955 | KB3: 46054 | KC3: 815146.38 | KD3: =KC3*P3*O3 -> 2498.8114 | KE3: 848168.89 | KF3: =KE3*P3*O3 -> 2600.0411 | KG3: =KD3+KF3 -> 5098.8526 | KI3: =KC3-KE3 -> -33022.505 | KJ3: =KI3*P3*O3 -> -101.22969 | KK3: 3.7638211 | KL3: =KK3*K3 -> 2617.6999 | KM3: 3.6903879 | KN3: =KM3*K3 -> 2566.6279 | KO3: =(KK3-KM3)*K3 -> 51.072035 | KQ3: 46054 | KR3: 799795.1 | KS3: =KR3*P3*O3 -> 2451.7524 | KT3: 797751.19 | KU3: =KT3*P3*O3 -> 2445.4869 | KV3: =KS3+KU3 -> 4897.2394 | KX3: =KR3-KT3 -> 2043.9055 | KY3: =KX3*P3*O3 -> 6.2655427 | KZ3: 3.5398742 | LA3: =KZ3*K3 -> 2461.9471 | LB3: 3.6212568 | LC3: =LB3*K3 -> 2518.5479 | LD3: =(KZ3-LB3)*K3 -> -56.600788 | LF3: 46054 | LG3: 833325.27 | LH3: =LG3*P3*O3 -> 2554.5384 | LI3: 824084.52 | LJ3: =LI3*P3*O3 -> 2526.2111 | LK3: =LH3+LJ3 -> 5080.7495 | LM3: =LG3-LI3 -> 9240.7578 | LN3: =LM3*P3*O3 -> 28.327319 | LO3: 40.073691 | LP3: =LO3*L3 -> 2476.1534 | LQ3: 41.338358 | LR3: =LQ3*L3 -> 2554.2971 | LS3: =(LO3-LQ3)*L3 -> -78.143768 | LU3: 46054 | LV3: 812761.82 | LW3: =LV3*P3*O3 -> 2491.5016 | LX3: 835632.22 | LY3: =LX3*P3*O3 -> 2561.6103 | LZ3: =LW3+LY3 -> 5053.1119 | MB3: =LV3-LX3 -> -22870.407 | MC3: =MB3*P3*O3 -> -70.108676 | MD3: 40.621065 | ME3: =MD3*L3 -> 2509.9756 | MF3: 40.317935 | MG3: =MF3*L3 -> 2491.2452 | MH3: =(MD3-MF3)*L3 -> 18.730454 | MJ3: 46054 | MK3: 811886.6 | ML3: =MK3*P3*O3 -> 2488.8187 | MM3: 821291.5 | MN3: =MM3*P3*O3 -> 2517.6492 | MO3: =ML3+MN3 -> 5006.4678 | MQ3: =MK3-MM3 -> -9404.9 | MR3: =MQ3*P3*O3 -> -28.830493 | MS3: 7.390996 | MT3: =MS3*M3 -> 2478.7922 | MU3: 7.454373 | MV3: =MU3*M3 -> 2500.0476 | MW3: =(MS3-MU3)*M3 -> -21.255378 | MY3: 46054 | MZ3: 776530.8 | NA3: =MZ3*P3*O3 -> 2380.4363 | NB3: 776992.2 | NC3: =NB3*P3*O3 -> 2381.8507 | ND3: =NA3+NC3 -> 4762.287 | NF3: =MZ3-NB3 -> -461.4 | NG3: =NF3*P3*O3 -> -1.4144105 | NH3: 6.991125 | NI3: =NH3*M3 -> 2344.6835 | NJ3: 7.128412 | NK3: =NJ3*M3 -> 2390.7268 | NL3: =(NH3-NJ3)*M3 -> -46.043314 | NN3: 46054 | NO3: 815211.2 | NP3: =NO3*P3*O3 -> 2499.0101 | NQ3: 813736.5 | NR3: =NQ3*P3*O3 -> 2494.4895 | NS3: =NP3+NR3 -> 4993.4996 | NU3: =NO3-NQ3 -> 1474.7 | NV3: =NU3*P3*O3 -> 4.520657 | NW3: 311958.8 | NX3: =NW3*N3 -> 2349.0498 | NY3: 325267.1 | NZ3: =NY3*N3 -> 2449.2613 | OA3: =(NW3-NY3)*N3 -> -100.2115 | OC3: 46054 | OD3: 800359.2 | OE3: =OD3*P3*O3 -> 2453.4817 | OF3: 784214.6 | OG3: =OF3*P3*O3 -> 2403.9908 | OH3: =OE3+OG3 -> 4857.4725 | OJ3: =OD3-OF3 -> 16144.6 | OK3: =OJ3*P3*O3 -> 49.490879 | OL3: 300340.9 | OM3: =OL3*N3 -> 2261.567 | ON3: 319412.8 | OO3: =ON3*N3 -> 2405.1784 | OP3: =(OL3-ON3)*N3 -> -143.61141
A4: 46055 | B4: 184.22 | C4: 95.8 | D4: 185.86 | E4: 417.3 | F4: 424.92 | G4: 0.0024 | H4: 4.27 | I4: 628.84 | J4: 141.84 | K4: 685.88 | L4: 61.29 | M4: 346.71 | N4: 0.00781 | O4: 99.596 | P4: 3.002e-05 | R4: 46055 | S4: 866861.57 | T4: =S4*P4*O4 -> 2591.8051 | U4: 873275.97 | V4: =U4*P4*O4 -> 2610.9833 | W4: =T4+V4 -> 5202.7884 | Y4: =S4-U4 -> -6414.3952 | Z4: =Y4*P4*O4 -> -19.17822 | AA4: 13.937149 | AB4: =AA4*B4 -> 2567.5015 | AC4: 14.115297 | AD4: =AC4*B4 -> 2600.32 | AE4: =(AA4-AC4)*B4 -> -32.818476 | AG4: 46055 | AH4: 875710.91 | AI4: =AH4*P4*O4 -> 2618.2635 | AJ4: 858340.74 | AK4: =AJ4*P4*O4 -> 2566.3289 | AL4: =AI4+AK4 -> 5184.5924 | AN4: =AH4-AJ4 -> 17370.17 | AO4: =AN4*P4*O4 -> 51.934583 | AP4: 13.697639 | AQ4: =AP4*B4 -> 2523.3791 | AR4: 14.262503 | AS4: =AR4*B4 -> 2627.4383 | AT4: =(AP4-AR4)*B4 -> -104.05921 | AV4: 46055 | AW4: 896156.03 | AX4: =AW4*P4*O4 -> 2679.3917 | AY4: 893735.84 | AZ4: =AY4*P4*O4 -> 2672.1557 | BA4: =AX4+AZ4 -> 5351.5474 | BC4: =AW4-AY4 -> 2420.1859 | BD4: =BC4*P4*O4 -> 7.2360458 | BE4: 28.389033 | BF4: =BE4*C4 -> 2719.6694 | BG4: 29.021731 | BH4: =BG4*C4 -> 2780.2819 | BI4: =(BE4-BG4)*C4 -> -60.612477 | BK4: 46055 | BL4: 848155.56 | BM4: =BL4*P4*O4 -> 2535.8765 | BN4: 854978.05 | BO4: =BN4*P4*O4 -> 2556.2749 | BP4: =BM4+BO4 -> 5092.1514 | BR4: =BL4-BN4 -> -6822.4885 | BS4: =BR4*P4*O4 -> -20.398367 | BT4: 27.152495 | BU4: =BT4*C4 -> 2601.2091 | BV4: 27.463329 | BW4: =BV4*C4 -> 2630.9869 | BX4: =(BT4-BV4)*C4 -> -29.777868 | BZ4: 46055 | CA4: 875326.14 | CB4: =CA4*P4*O4 -> 2617.113 | CC4: 867345.28 | CD4: =CC4*P4*O4 -> 2593.2513 | CE4: =CB4+CD4 -> 5210.3643 | CG4: =CA4-CC4 -> 7980.8569 | CH4: =CG4*P4*O4 -> 23.86174 | CI4: 13.805881 | CJ4: =CI4*D4 -> 2565.9611 | CK4: 14.212704 | CL4: =CK4*D4 -> 2641.5732 | CM4: =(CI4-CK4)*D4 -> -75.612119 | CO4: 46055 | CP4: 878085.3 | CQ4: =CP4*P4*O4 -> 2625.3626 | CR4: 883892.18 | CS4: =CR4*P4*O4 -> 2642.7244 | CT4: =CQ4+CS4 -> 5268.087 | CV4: =CP4-CR4 -> -5806.8829 | CW4: =CV4*P4*O4 -> -17.361836 | CX4: 14.067666 | CY4: =CX4*D4 -> 2614.6165 | CZ4: 14.258186 | DA4: =CZ4*D4 -> 2650.0264 | DB4: =(CX4-CZ4)*D4 -> -35.409917 | DD4: 46055 | DE4: 871187.27 | DF4: =DE4*P4*O4 -> 2604.7384 | DG4: 887965.46 | DH4: =DG4*P4*O4 -> 2654.903 | DI4: =DF4+DH4 -> 5259.6414 | DK4: =DE4-DG4 -> -16778.186 | DL4: =DK4*P4*O4 -> -50.164628 | DM4: 6.1741795 | DN4: =DM4*E4 -> 2576.4851 | DO4: 6.1793716 | DP4: =DO4*E4 -> 2578.6518 | DQ4: =(DM4-DO4)*E4 -> -2.1666842 | DS4: 46055 | DT4: 865979.06 | DU4: =DT4*P4*O4 -> 2589.1665 | DV4: 881923.76 | DW4: =DV4*P4*O4 -> 2636.8391 | DX4: =DU4+DW4 -> 5226.0055 | DZ4: =DT4-DV4 -> -15944.698 | EA4: =DZ4*P4*O4 -> -47.672604 | EB4: 6.1321148 | EC4: =EB4*E4 -> 2558.9315 | ED4: 6.1455366 | EE4: =ED4*E4 -> 2564.5324 | EF4: =(EB4-ED4)*E4 -> -5.600913 | EH4: 46055 | EI4: 2476433 | EJ4: =EI4*P4*O4 -> 7404.2175 | EK4: 2448965 | EL4: =EK4*P4*O4 -> 7322.0917 | EM4: =EJ4+EL4 -> 14726.309 | EO4: =EI4-EK4 -> 27468 | EP4: =EO4*P4*O4 -> 82.125802 | EQ4: 17.4526 | ER4: =EQ4*F4 -> 7415.9588 | ES4: 17.72748 | ET4: =ES4*F4 -> 7532.7608 | EU4: =(EQ4-ES4)*F4 -> -116.80201 | EW4: 46055 | EX4: 2426262 | EY4: =EX4*P4*O4 -> 7254.2126 | EZ4: 2429078 | FA4: =EZ4*P4*O4 -> 7262.6321 | FB4: =EY4+FA4 -> 14516.845 | FD4: =EX4-EZ4 -> -2816 | FE4: =FD4*P4*O4 -> -8.4194793 | FF4: 17.28975 | FG4: =FF4*F4 -> 7346.7606 | FH4: 17.37343 | FI4: =FH4*F4 -> 7382.3179 | FJ4: =(FF4-FH4)*F4 -> -35.557306 | FL4: 46055 | FM4: 677937.8 | FN4: =FM4*P4*O4 -> 2026.9472 | FO4: 697250.7 | FP4: =FO4*P4*O4 -> 2084.6903 | FQ4: =FN4+FP4 -> 4111.6375 | FS4: =FM4-FO4 -> -19312.9 | FT4: =FS4*P4*O4 -> -57.743097 | FU4: 832456 | FV4: =FU4*G4 -> 1997.8944 | FW4: 842380.1 | FX4: =FW4*G4 -> 2021.7122 | FY4: =(FU4-FW4)*G4 -> -23.81784 | GA4: 46055 | GB4: 671135.2 | GC4: =GB4*P4*O4 -> 2006.6083 | GD4: 670421.9 | GE4: =GD4*P4*O4 -> 2004.4756 | GF4: =GC4+GE4 -> 4011.0839 | GH4: =GB4-GD4 -> 713.3 | GI4: =GH4*P4*O4 -> 2.1326756 | GJ4: 800081.3 | GK4: =GJ4*G4 -> 1920.1951 | GL4: 834224.3 | GM4: =GL4*G4 -> 2002.1383 | GN4: =(GJ4-GL4)*G4 -> -81.9432 | GP4: 46055 | GQ4: 688044.4 | GR4: =GQ4*P4*O4 -> 2057.1646 | GS4: 706752.2 | GT4: =GS4*P4*O4 -> 2113.0986 | GU4: =GR4+GT4 -> 4170.2632 | GW4: =GQ4-GS4 -> -18707.8 | GX4: =GW4*P4*O4 -> -55.933926 | GY4: 500.2855 | GZ4: =GY4*H4 -> 2136.2191 | HA4: 506.8781 | HB4: =HA4*H4 -> 2164.3695 | HC4: =(GY4-HA4)*H4 -> -28.150402 | HE4: 46055 | HF4: 667565.4 | HG4: =HF4*P4*O4 -> 1995.935 | HH4: 677780.4 | HI4: =HH4*P4*O4 -> 2026.4766 | HJ4: =HG4+HI4 -> 4022.4116 | HL4: =HF4-HH4 -> -10215 | HM4: =HL4*P4*O4 -> -30.541542 | HN4: 479.3343 | HO4: =HN4*H4 -> 2046.7575 | HP4: 491.8617 | HQ4: =HP4*H4 -> 2100.2495 | HR4: =(HN4-HP4)*H4 -> -53.491998 | HT4: 46055 | HV4: =HU4*P4*O4 -> 0 | HX4: =HW4*P4*O4 -> 0 | HY4: =HV4+HX4 -> 0 | IA4: =HU4-HW4 -> 0 | IB4: =IA4*P4*O4 -> 0 | ID4: =IC4*I4 -> 0 | IF4: =IE4*I4 -> 0 | IG4: =(IC4-IE4)*I4 -> 0 | II4: 46055 | IK4: =IJ4*P4*O4 -> 0 | IM4: =IL4*P4*O4 -> 0 | IN4: =IK4+IM4 -> 0 | IP4: =IJ4-IL4 -> 0 | IQ4: =IP4*P4*O4 -> 0 | IS4: =IR4*I4 -> 0 | IU4: =IT4*I4 -> 0 | IV4: =(IR4-IT4)*I4 -> 0 | IX4: 46055 | IY4: 869240.8 | IZ4: =IY4*P4*O4 -> 2598.9187 | JA4: 887828.6 | JB4: =JA4*P4*O4 -> 2654.4938 | JC4: =IZ4+JB4 -> 5253.4125 | JE4: =IY4-JA4 -> -18587.8 | JF4: =JE4*P4*O4 -> -55.575141 | JG4: 18.96155 | JH4: =JG4*J4 -> 2689.5063 | JI4: 18.93122 | JJ4: =JI4*J4 -> 2685.2042 | JK4: =(JG4-JI4)*J4 -> 4.3020072 | JM4: 46055 | JN4: 862233.3 | JO4: =JN4*P4*O4 -> 2577.9671 | JP4: 875968.8 | JQ4: =JP4*P4*O4 -> 2619.0345 | JR4: =JO4+JQ4 -> 5197.0017 | JT4: =JN4-JP4 -> -13735.5 | JU4: =JT4*P4*O4 -> -41.067386 | JV4: 18.70494 | JW4: =JV4*J4 -> 2653.1087 | JX4: 18.80355 | JY4: =JX4*J4 -> 2667.0955 | JZ4: =(JV4-JX4)*J4 -> -13.986842 | KB4: 46055 | KC4: 895760.08 | KD4: =KC4*P4*O4 -> 2678.2079 | KE4: 899793.28 | KF4: =KE4*P4*O4 -> 2690.2667 | KG4: =KD4+KF4 -> 5368.4746 | KI4: =KC4-KE4 -> -4033.2015 | KJ4: =KI4*P4*O4 -> -12.058756 | KK4: 3.9894493 | KL4: =KK4*K4 -> 2736.2835 | KM4: 4.0512843 | KN4: =KM4*K4 -> 2778.6948 | KO4: =(KK4-KM4)*K4 -> -42.411362 | KQ4: 46055 | KR4: 862252.96 | KS4: =KR4*P4*O4 -> 2578.0259 | KT4: 870029.04 | KU4: =KT4*P4*O4 -> 2601.2754 | KV4: =KS4+KU4 -> 5179.3013 | KX4: =KR4-KT4 -> -7776.0777 | KY4: =KX4*P4*O4 -> -23.249476 | KZ4: 3.857264 | LA4: =KZ4*K4 -> 2645.6202 | LB4: 3.9011861 | LC4: =LB4*K4 -> 2675.7455 | LD4: =(KZ4-LB4)*K4 -> -30.125303 | LF4: 46055 | LG4: 878434.89 | LH4: =LG4*P4*O4 -> 2626.4078 | LI4: 898684.69 | LJ4: =LI4*P4*O4 -> 2686.9521 | LK4: =LH4+LJ4 -> 5313.3599 | LM4: =LG4-LI4 -> -20249.804 | LN4: =LM4*P4*O4 -> -60.544321 | LO4: 43.987968 | LP4: =LO4*L4 -> 2696.0226 | LQ4: 43.853834 | LR4: =LQ4*L4 -> 2687.8015 | LS4: =(LO4-LQ4)*L4 -> 8.2210833 | LU4: 46055 | LV4: 807611.84 | LW4: =LV4*P4*O4 -> 2414.656 | LX4: 792223.12 | LY4: =LX4*P4*O4 -> 2368.6456 | LZ4: =LW4+LY4 -> 4783.3016 | MB4: =LV4-LX4 -> 15388.723 | MC4: =MB4*P4*O4 -> 46.01031 | MD4: 38.763442 | ME4: =MD4*L4 -> 2375.8113 | MF4: 40.334206 | MG4: =MF4*L4 -> 2472.0835 | MH4: =(MD4-MF4)*L4 -> -96.272146 | MJ4: 46055 | MK4: 892003.4 | ML4: =MK4*P4*O4 -> 2666.9759 | MM4: 896679.2 | MN4: =MM4*P4*O4 -> 2680.956 | MO4: =ML4+MN4 -> 5347.9319 | MQ4: =MK4-MM4 -> -4675.8 | MR4: =MQ4*P4*O4 -> -13.980043 | MS4: 7.94816 | MT4: =MS4*M4 -> 2755.7066 | MU4: 8.065164 | MV4: =MU4*M4 -> 2796.273 | MW4: =(MS4-MU4)*M4 -> -40.566457 | MY4: 46055 | MZ4: 858898.9 | NA4: =MZ4*P4*O4 -> 2567.9977 | NB4: 866888.9 | NC4: =NB4*P4*O4 -> 2591.8868 | ND4: =NA4+NC4 -> 5159.8845 | NF4: =MZ4-NB4 -> -7990 | NG4: =NF4*P4*O4 -> -23.889077 | NH4: 7.683984 | NI4: =NH4*M4 -> 2664.1141 | NJ4: 7.770949 | NK4: =NJ4*M4 -> 2694.2657 | NL4: =(NH4-NJ4)*M4 -> -30.151635 | NN4: 46055 | NO4: 864679.3 | NP4: =NO4*P4*O4 -> 2585.2804 | NQ4: 856389.4 | NR4: =NQ4*P4*O4 -> 2560.4946 | NS4: =NP4+NR4 -> 5145.775 | NU4: =NO4-NQ4 -> 8289.9 | NV4: =NU4*P4*O4 -> 24.785739 | NW4: 332694.4 | NX4: =NW4*N4 -> 2598.3433 | NY4: 349609.9 | NZ4: =NY4*N4 -> 2730.4533 | OA4: =(NW4-NY4)*N4 -> -132.11005 | OC4: 46055 | OD4: 835759.8 | OE4: =OD4*P4*O4 -> 2498.8148 | OF4: 848790.9 | OG4: =OF4*P4*O4 -> 2537.7761 | OH4: =OE4+OG4 -> 5036.5908 | OJ4: =OD4-OF4 -> -13031.1 | OK4: =OJ4*P4*O4 -> -38.96132 | OL4: 329644.7 | OM4: =OL4*N4 -> 2574.5251 | ON4: 337948.1 | OO4: =ON4*N4 -> 2639.3747 | OP4: =(OL4-ON4)*N4 -> -64.849554
A5: 46056 | B5: 188.32 | C5: 91.07 | D5: 186.72 | E5: 435.48 | F5: 427.2 | G5: 0.00247 | H5: 4.267 | I5: 628.81 | J5: 142.11 | K5: 698.23 | L5: 59.9 | M5: 350.34 | N5: 0.00775 | O5: 104.961 | P5: 2.911e-05 | R5: 46056 | S5: 412479.22 | T5: =S5*P5*O5 -> 1260.2951 | U5: 337854.68 | V5: =U5*P5*O5 -> 1032.2862 | W5: =T5+V5 -> 2292.5812 | Y5: =S5-U5 -> 74624.538 | Z5: =Y5*P5*O5 -> 228.00891 | AA5: 5.4834777 | AB5: =AA5*B5 -> 1032.6485 | AC5: 6.8260938 | AD5: =AC5*B5 -> 1285.49 | AE5: =(AA5-AC5)*B5 -> -252.84148 | AG5: 46056 | AH5: 921424.16 | AI5: =AH5*P5*O5 -> 2815.3329 | AJ5: 866916.93 | AK5: =AJ5*P5*O5 -> 2648.7907 | AL5: =AI5+AK5 -> 5464.1237 | AN5: =AH5-AJ5 -> 54507.232 | AO5: =AN5*P5*O5 -> 166.5422 | AP5: 13.919482 | AQ5: =AP5*B5 -> 2621.3168 | AR5: 15.110929 | AS5: =AR5*B5 -> 2845.6902 | AT5: =(AP5-AR5)*B5 -> -224.3734 | AV5: 46056 | AW5: 908404.72 | AX5: =AW5*P5*O5 -> 2775.5531 | AY5: 844228.51 | AZ5: =AY5*P5*O5 -> 2579.4682 | BA5: =AX5+AZ5 -> 5355.0213 | BC5: =AW5-AY5 -> 64176.213 | BD5: =BC5*P5*O5 -> 196.08494 | BE5: 28.043135 | BF5: =BE5*C5 -> 2553.8883 | BG5: 30.812245 | BH5: =BG5*C5 -> 2806.0712 | BI5: =(BE5-BG5)*C5 -> -252.18287 | BK5: 46056 | BL5: 864077.68 | BM5: =BL5*P5*O5 -> 2640.1157 | BN5: 789080.01 | BO5: =BN5*P5*O5 -> 2410.9667 | BP5: =BM5+BO5 -> 5051.0823 | BR5: =BL5-BN5 -> 74997.669 | BS5: =BR5*P5*O5 -> 229.14898 | BT5: 26.2198 | BU5: =BT5*C5 -> 2387.8372 | BV5: 29.318526 | BW5: =BV5*C5 -> 2670.0381 | BX5: =(BT5-BV5)*C5 -> -282.20094 | BZ5: 46056 | CA5: 869507.26 | CB5: =CA5*P5*O5 -> 2656.7053 | CC5: 895251.39 | CD5: =CC5*P5*O5 -> 2735.3643 | CE5: =CB5+CD5 -> 5392.0695 | CG5: =CA5-CC5 -> -25744.13 | CH5: =CG5*P5*O5 -> -78.658994 | CI5: 14.465306 | CJ5: =CI5*D5 -> 2700.962 | CK5: 14.331692 | CL5: =CK5*D5 -> 2676.0136 | CM5: =(CI5-CK5)*D5 -> 24.948408 | CO5: 46056 | CP5: 834099.37 | CQ5: =CP5*P5*O5 -> 2548.5195 | CR5: 842735.77 | CS5: =CR5*P5*O5 -> 2574.9073 | CT5: =CQ5+CS5 -> 5123.4267 | CV5: =CP5-CR5 -> -8636.3996 | CW5: =CV5*P5*O5 -> -26.387782 | CX5: 13.609102 | CY5: =CX5*D5 -> 2541.0916 | CZ5: 13.747189 | DA5: =CZ5*D5 -> 2566.8751 | DB5: =(CX5-CZ5)*D5 -> -25.783493 | DD5: 46056 | DE5: 926219.91 | DF5: =DE5*P5*O5 -> 2829.9859 | DG5: 830766.41 | DH5: =DG5*P5*O5 -> 2538.3359 | DI5: =DF5+DH5 -> 5368.3218 | DK5: =DE5-DG5 -> 95453.494 | DL5: =DK5*P5*O5 -> 291.65001 | DM5: 5.5778378 | DN5: =DM5*E5 -> 2429.0368 | DO5: 6.3246349 | DP5: =DO5*E5 -> 2754.252 | DQ5: =(DM5-DO5)*E5 -> -325.21517 | DS5: 46056 | DT5: 989113.46 | DU5: =DT5*P5*O5 -> 3022.1518 | DV5: 905769.93 | DW5: =DV5*P5*O5 -> 2767.5028 | DX5: =DU5+DW5 -> 5789.6546 | DZ5: =DT5-DV5 -> 83343.534 | EA5: =DZ5*P5*O5 -> 254.64906 | EB5: 6.0634417 | EC5: =EB5*E5 -> 2640.5076 | ED5: 6.7436706 | EE5: =ED5*E5 -> 2936.7337 | EF5: =(EB5-ED5)*E5 -> -296.22605 | EH5: 46056 | EI5: 2597261 | EJ5: =EI5*P5*O5 -> 7935.7095 | EK5: 2589908 | EL5: =EK5*P5*O5 -> 7913.243 | EM5: =EJ5+EL5 -> 15848.952 | EO5: =EI5-EK5 -> 7353 | EP5: =EO5*P5*O5 -> 22.466464 | EQ5: 18.36791 | ER5: =EQ5*F5 -> 7846.7712 | ES5: 18.50802 | ET5: =ES5*F5 -> 7906.6261 | EU5: =(EQ5-ES5)*F5 -> -59.854992 | EW5: 46056 | EX5: 2490312 | EY5: =EX5*P5*O5 -> 7608.9359 | EZ5: 2482139 | FA5: =EZ5*P5*O5 -> 7583.964 | FB5: =EY5+FA5 -> 15192.9 | FD5: =EX5-EZ5 -> 8173 | FE5: =FD5*P5*O5 -> 24.971904 | FF5: 17.59151 | FG5: =FF5*F5 -> 7515.0931 | FH5: 17.74578 | FI5: =FH5*F5 -> 7580.9972 | FJ5: =(FF5-FH5)*F5 -> -65.904144 | FL5: 46056 | FM5: 653239.6 | FN5: =FM5*P5*O5 -> 1995.9179 | FO5: 676528.1 | FP5: =FO5*P5*O5 -> 2067.0739 | FQ5: =FN5+FP5 -> 4062.9918 | FS5: =FM5-FO5 -> -23288.5 | FT5: =FS5*P5*O5 -> -71.156025 | FU5: 817847.2 | FV5: =FU5*G5 -> 2020.0826 | FW5: 824156.7 | FX5: =FW5*G5 -> 2035.667 | FY5: =(FU5-FW5)*G5 -> -15.584465 | GA5: 46056 | GB5: 623028.8 | GC5: =GB5*P5*O5 -> 1903.6114 | GD5: 645354.3 | GE5: =GD5*P5*O5 -> 1971.825 | GF5: =GC5+GE5 -> 3875.4364 | GH5: =GB5-GD5 -> -22325.5 | GI5: =GH5*P5*O5 -> -68.213661 | GJ5: 781070.9 | GK5: =GJ5*G5 -> 1929.2451 | GL5: 785594.5 | GM5: =GL5*G5 -> 1940.4184 | GN5: =(GJ5-GL5)*G5 -> -11.173292 | GP5: 46056 | GQ5: 649088.5 | GR5: =GQ5*P5*O5 -> 1983.2346 | GS5: 666007 | GT5: =GS5*P5*O5 -> 2034.9276 | GU5: =GR5+GT5 -> 4018.1621 | GW5: =GQ5-GS5 -> -16918.5 | GX5: =GW5*P5*O5 -> -51.693034 | GY5: 469.2884 | GZ5: =GY5*H5 -> 2002.4536 | HA5: 476.2266 | HB5: =HA5*H5 -> 2032.0589 | HC5: =(GY5-HA5)*H5 -> -29.605299 | HE5: 46056 | HF5: 683958.6 | HG5: =HF5*P5*O5 -> 2089.7772 | HH5: 693262.5 | HI5: =HH5*P5*O5 -> 2118.2044 | HJ5: =HG5+HI5 -> 4207.9816 | HL5: =HF5-HH5 -> -9303.9 | HM5: =HL5*P5*O5 -> -28.427273 | HN5: 488.4034 | HO5: =HN5*H5 -> 2084.0173 | HP5: 501.7947 | HQ5: =HP5*H5 -> 2141.158 | HR5: =(HN5-HP5)*H5 -> -57.140677 | HT5: 46056 | HU5: 665943.7 | HV5: =HU5*P5*O5 -> 2034.7342 | HW5: 686918.5 | HX5: =HW5*P5*O5 -> 2098.8209 | HY5: =HV5+HX5 -> 4133.5551 | IA5: =HU5-HW5 -> -20974.8 | IB5: =IA5*P5*O5 -> -64.086712 | IC5: 3.278776 | ID5: =IC5*I5 -> 2061.7271 | IE5: 3.308472 | IF5: =IE5*I5 -> 2080.4003 | IG5: =(IC5-IE5)*I5 -> -18.673142 | II5: 46056 | IJ5: 692705.9 | IK5: =IJ5*P5*O5 -> 2116.5038 | IL5: 695374.9 | IM5: =IL5*P5*O5 -> 2124.6587 | IN5: =IK5+IM5 -> 4241.1625 | IP5: =IJ5-IL5 -> -2669 | IQ5: =IP5*P5*O5 -> -8.1549019 | IR5: 3.31896 | IS5: =IR5*I5 -> 2086.9952 | IT5: 3.441941 | IU5: =IT5*I5 -> 2164.3269 | IV5: =(IR5-IT5)*I5 -> -77.331683 | IX5: 46056 | IY5: 981841.7 | IZ5: =IY5*P5*O5 -> 2999.9336 | JA5: 954879.1 | JB5: =JA5*P5*O5 -> 2917.5516 | JC5: =IZ5+JB5 -> 5917.4852 | JE5: =IY5-JA5 -> 26962.6 | JF5: =JE5*P5*O5 -> 82.381925 | JG5: 20.68096 | JH5: =JG5*J5 -> 2938.9712 | JI5: 21.68892 | JJ5: =JI5*J5 -> 3082.2124 | JK5: =(JG5-JI5)*J5 -> -143.2412 | JM5: 46056 | JN5: 964721.8 | JO5: =JN5*P5*O5 -> 2947.6252 | JP5: 931138.7 | JQ5: =JP5*P5*O5 -> 2845.0149 | JR5: =JO5+JQ5 -> 5792.6401 | JT5: =JN5-JP5 -> 33583.1 | JU5: =JT5*P5*O5 -> 102.6103 | JV5: 20.17622 | JW5: =JV5*J5 -> 2867.2426 | JX5: 21.33514 | JY5: =JX5*J5 -> 3031.9367 | JZ5: =(JV5-JX5)*J5 -> -164.69412 | KB5: 46056 | KC5: 984686.11 | KD5: =KC5*P5*O5 -> 3008.6244 | KE5: 943324.17 | KF5: =KE5*P5*O5 -> 2882.2465 | KG5: =KD5+KF5 -> 5890.871 | KI5: =KC5-KE5 -> 41361.941 | KJ5: =KI5*P5*O5 -> 126.37788 | KK5: 4.1450603 | KL5: =KK5*K5 -> 2894.2055 | KM5: 4.4141426 | KN5: =KM5*K5 -> 3082.0868 | KO5: =(KK5-KM5)*K5 -> -187.88129 | KQ5: 46056 | KR5: 971466.72 | KS5: =KR5*P5*O5 -> 2968.2337 | KT5: 943243.43 | KU5: =KT5*P5*O5 -> 2881.9999 | KV5: =KS5+KU5 -> 5850.2336 | KX5: =KR5-KT5 -> 28223.288 | KY5: =KX5*P5*O5 -> 86.233851 | KZ5: 4.1452286 | LA5: =KZ5*K5 -> 2894.3229 | LB5: 4.3578169 | LC5: =LB5*K5 -> 3042.7585 | LD5: =(KZ5-LB5)*K5 -> -148.43554 | LF5: 46056 | LG5: 896241.53 | LH5: =LG5*P5*O5 -> 2738.3895 | LI5: 840060.73 | LJ5: =LI5*P5*O5 -> 2566.7339 | LK5: =LH5+LJ5 -> 5305.1234 | LM5: =LG5-LI5 -> 56180.801 | LN5: =LM5*P5*O5 -> 171.65564 | LO5: 43.243574 | LP5: =LO5*L5 -> 2590.2901 | LQ5: 47.283491 | LR5: =LQ5*L5 -> 2832.2811 | LS5: =(LO5-LQ5)*L5 -> -241.99106 | LU5: 46056 | LV5: 650643.35 | LW5: =LV5*P5*O5 -> 1987.9853 | LX5: 611727.02 | LY5: =LX5*P5*O5 -> 1869.0797 | LZ5: =LW5+LY5 -> 3857.065 | MB5: =LV5-LX5 -> 38916.327 | MC5: =MB5*P5*O5 -> 118.90552 | MD5: 31.634378 | ME5: =MD5*L5 -> 1894.8992 | MF5: 34.574489 | MG5: =MF5*L5 -> 2071.0119 | MH5: =(MD5-MF5)*L5 -> -176.11262 | MJ5: 46056 | MK5: 974462.6 | ML5: =MK5*P5*O5 -> 2977.3874 | MM5: 943433.4 | MN5: =MM5*P5*O5 -> 2882.5803 | MO5: =ML5+MN5 -> 5859.9677 | MQ5: =MK5-MM5 -> 31029.2 | MR5: =MQ5*P5*O5 -> 94.807074 | MS5: 8.155119 | MT5: =MS5*M5 -> 2857.0644 | MU5: 8.593624 | MV5: =MU5*M5 -> 3010.6902 | MW5: =(MS5-MU5)*M5 -> -153.62584 | MY5: 46056 | MZ5: 958521.8 | NA5: =MZ5*P5*O5 -> 2928.6816 | NB5: 916495.7 | NC5: =NB5*P5*O5 -> 2800.2744 | ND5: =NA5+NC5 -> 5728.9561 | NF5: =MZ5-NB5 -> 42026.1 | NG5: =NF5*P5*O5 -> 128.40716 | NH5: 7.921914 | NI5: =NH5*M5 -> 2775.3634 | NJ5: 8.457311 | NK5: =NJ5*M5 -> 2962.9343 | NL5: =(NH5-NJ5)*M5 -> -187.57098 | NN5: 46056 | NO5: 943647.3 | NP5: =NO5*P5*O5 -> 2883.2338 | NQ5: 932207.2 | NR5: =NQ5*P5*O5 -> 2848.2796 | NS5: =NP5+NR5 -> 5731.5134 | NU5: =NO5-NQ5 -> 11440.1 | NV5: =NU5*P5*O5 -> 34.95425 | NW5: 359019.8 | NX5: =NW5*N5 -> 2782.4034 | NY5: 378373.5 | NZ5: =NY5*N5 -> 2932.3946 | OA5: =(NW5-NY5)*N5 -> -149.99118 | OC5: 46056 | OD5: 925857.7 | OE5: =OD5*P5*O5 -> 2828.8792 | OF5: 902384.1 | OG5: =OF5*P5*O5 -> 2757.1577 | OH5: =OE5+OG5 -> 5586.0369 | OJ5: =OD5-OF5 -> 23473.6 | OK5: =OJ5*P5*O5 -> 71.721583 | OL5: 347418 | OM5: =OL5*N5 -> 2692.4895 | ON5: 371191.7 | OO5: =ON5*N5 -> 2876.7357 | OP5: =(OL5-ON5)*N5 -> -184.24618
A6: 46057 | B6: 179.32 | C6: 86.99 | D6: 179.81 | E6: 464.18 | F6: 420.09 | G6: 0.00243 | H6: 4.258 | I6: 617.47 | J6: 132.74 | K6: 690.71 | L6: 55.93 | M6: 344.14 | N6: 0.00757 | O6: 98.776 | P6: 3.038e-05 | R6: 46057 | S6: 899897.65 | T6: =S6*P6*O6 -> 2700.4263 | U6: 963352.87 | V6: =U6*P6*O6 -> 2890.8436 | W6: =T6+V6 -> 5591.2699 | Y6: =S6-U6 -> -63455.218 | Z6: =Y6*P6*O6 -> -190.41736 | AA6: 16.040161 | AB6: =AA6*B6 -> 2876.3216 | AC6: 15.29311 | AD6: =AC6*B6 -> 2742.3605 | AE6: =(AA6-AC6)*B6 -> 133.9611 | AG6: 46057 | AH6: 892337.82 | AI6: =AH6*P6*O6 -> 2677.7406 | AJ6: 964548.03 | AK6: =AJ6*P6*O6 -> 2894.4301 | AL6: =AI6+AK6 -> 5572.1707 | AN6: =AH6-AJ6 -> -72210.219 | AO6: =AN6*P6*O6 -> -216.6895 | AP6: 16.053734 | AQ6: =AP6*B6 -> 2878.7557 | AR6: 15.156762 | AS6: =AR6*B6 -> 2717.9105 | AT6: =(AP6-AR6)*B6 -> 160.84516 | AV6: 46057 | AW6: 916921.62 | AX6: =AW6*P6*O6 -> 2751.512 | AY6: 965198.37 | AZ6: =AY6*P6*O6 -> 2896.3816 | BA6: =AX6+AZ6 -> 5647.8937 | BC6: =AW6-AY6 -> -48276.753 | BD6: =BC6*P6*O6 -> -144.8696 | BE6: 33.532212 | BF6: =BE6*C6 -> 2916.9671 | BG6: 32.555739 | BH6: =BG6*C6 -> 2832.0237 | BI6: =(BE6-BG6)*C6 -> 84.943373 | BK6: 46057 | BL6: 879324.55 | BM6: =BL6*P6*O6 -> 2638.6902 | BN6: 940316.41 | BO6: =BN6*P6*O6 -> 2821.7155 | BP6: =BM6+BO6 -> 5460.4057 | BR6: =BL6-BN6 -> -60991.867 | BS6: =BR6*P6*O6 -> -183.0253 | BT6: 32.670393 | BU6: =BT6*C6 -> 2841.9975 | BV6: 31.213562 | BW6: =BV6*C6 -> 2715.2678 | BX6: =(BT6-BV6)*C6 -> 126.72966 | BZ6: 46057 | CA6: 967585.53 | CB6: =CA6*P6*O6 -> 2903.5451 | CC6: 914705.68 | CD6: =CC6*P6*O6 -> 2744.8624 | CE6: =CB6+CD6 -> 5648.4075 | CG6: =CA6-CC6 -> 52879.857 | CH6: =CG6*P6*O6 -> 158.68266 | CI6: 14.997471 | CJ6: =CI6*D6 -> 2696.6953 | CK6: 16.181256 | CL6: =CK6*D6 -> 2909.5516 | CM6: =(CI6-CK6)*D6 -> -212.85627 | CO6: 46057 | CP6: 922234.48 | CQ6: =CP6*P6*O6 -> 2767.455 | CR6: 902222.9 | CS6: =CR6*P6*O6 -> 2707.4039 | CT6: =CQ6+CS6 -> 5474.8588 | CV6: =CP6-CR6 -> 20011.587 | CW6: =CV6*P6*O6 -> 60.051068 | CX6: 14.781465 | CY6: =CX6*D6 -> 2657.8552 | CZ6: 15.423583 | DA6: =CZ6*D6 -> 2773.3144 | DB6: =(CX6-CZ6)*D6 -> -115.45915 | DD6: 46057 | DE6: 924936.08 | DF6: =DE6*P6*O6 -> 2775.562 | DG6: 971195.16 | DH6: =DG6*P6*O6 -> 2914.3769 | DI6: =DF6+DH6 -> 5689.9389 | DK6: =DE6-DG6 -> -46259.08 | DL6: =DK6*P6*O6 -> -138.81494 | DM6: 6.1539933 | DN6: =DM6*E6 -> 2856.5606 | DO6: 5.9739471 | DP6: =DO6*E6 -> 2772.9867 | DQ6: =(DM6-DO6)*E6 -> 83.57385 | DS6: 46057 | DT6: 888181.13 | DU6: =DT6*P6*O6 -> 2665.2671 | DV6: 954786.74 | DW6: =DV6*P6*O6 -> 2865.1383 | DX6: =DU6+DW6 -> 5530.4054 | DZ6: =DT6-DV6 -> -66605.615 | EA6: =DZ6*P6*O6 -> -199.87112 | EB6: 6.0476519 | EC6: =EB6*E6 -> 2807.199 | ED6: 5.7381815 | EE6: =ED6*E6 -> 2663.5491 | EF6: =(EB6-ED6)*E6 -> 143.64997 | EH6: 46057 | EI6: 2518169 | EJ6: =EI6*P6*O6 -> 7556.559 | EK6: 2596830 | EL6: =EK6*P6*O6 -> 7792.6061 | EM6: =EJ6+EL6 -> 15349.165 | EO6: =EI6-EK6 -> -78661 | EP6: =EO6*P6*O6 -> -236.0471 | EQ6: 18.39997 | ER6: =EQ6*F6 -> 7729.6434 | ES6: 17.94194 | ET6: =ES6*F6 -> 7537.2296 | EU6: =(EQ6-ES6)*F6 -> 192.41382 | EW6: 46057 | EX6: 2450886 | EY6: =EX6*P6*O6 -> 7354.6552 | EZ6: 2533823 | FA6: =EZ6*P6*O6 -> 7603.5338 | FB6: =EY6+FA6 -> 14958.189 | FD6: =EX6-EZ6 -> -82937 | FE6: =FD6*P6*O6 -> -248.87858 | FF6: 17.94411 | FG6: =FF6*F6 -> 7538.1412 | FH6: 17.46752 | FI6: =FH6*F6 -> 7337.9305 | FJ6: =(FF6-FH6)*F6 -> 200.21069 | FL6: 46057 | FM6: 743529.2 | FN6: =FM6*P6*O6 -> 2231.1935 | FO6: 700406.9 | FP6: =FO6*P6*O6 -> 2101.7914 | FQ6: =FN6+FP6 -> 4332.9849 | FS6: =FM6-FO6 -> 43122.3 | FT6: =FS6*P6*O6 -> 129.40204 | FU6: 859984.4 | FV6: =FU6*G6 -> 2089.7621 | FW6: 949137.1 | FX6: =FW6*G6 -> 2306.4032 | FY6: =(FU6-FW6)*G6 -> -216.64106 | GA6: 46057 | GB6: 707822.8 | GC6: =GB6*P6*O6 -> 2124.0452 | GD6: 674738.2 | GE6: =GD6*P6*O6 -> 2024.7644 | GF6: =GC6+GE6 -> 4148.8096 | GH6: =GB6-GD6 -> 33084.6 | GI6: =GH6*P6*O6 -> 99.28076 | GJ6: 828336.9 | GK6: =GJ6*G6 -> 2012.8587 | GL6: 903685.8 | GM6: =GL6*G6 -> 2195.9565 | GN6: =(GJ6-GL6)*G6 -> -183.09783 | GP6: 46057 | GQ6: 725161.9 | GR6: =GQ6*P6*O6 -> 2176.0766 | GS6: 685449.5 | GT6: =GS6*P6*O6 -> 2056.9071 | GU6: =GR6+GT6 -> 4232.9837 | GW6: =GQ6-GS6 -> 39712.4 | GX6: =GW6*P6*O6 -> 119.16956 | GY6: 479.626 | GZ6: =GY6*H6 -> 2042.2475 | HA6: 528.2805 | HB6: =HA6*H6 -> 2249.4184 | HC6: =(GY6-HA6)*H6 -> -207.17086 | HE6: 46057 | HF6: 685538.1 | HG6: =HF6*P6*O6 -> 2057.1729 | HH6: 656151.7 | HI6: =HH6*P6*O6 -> 1968.9898 | HJ6: =HG6+HI6 -> 4026.1627 | HL6: =HF6-HH6 -> 29386.4 | HM6: =HL6*P6*O6 -> 88.183146 | HN6: 458.8881 | HO6: =HN6*H6 -> 1953.9455 | HP6: 499.41 | HQ6: =HP6*H6 -> 2126.4878 | HR6: =(HN6-HP6)*H6 -> -172.54225 | HT6: 46057 | HU6: 744763.6 | HV6: =HU6*P6*O6 -> 2234.8977 | HW6: 707262.4 | HX6: =HW6*P6*O6 -> 2122.3635 | HY6: =HV6+HX6 -> 4357.2612 | IA6: =HU6-HW6 -> 37501.2 | IB6: =IA6*P6*O6 -> 112.53416 | IC6: 3.343158 | ID6: =IC6*I6 -> 2064.2998 | IE6: 3.665312 | IF6: =IE6*I6 -> 2263.2202 | IG6: =(IC6-IE6)*I6 -> -198.92043 | II6: 46057 | IJ6: 728540.5 | IK6: =IJ6*P6*O6 -> 2186.2152 | IL6: 692300.9 | IM6: =IL6*P6*O6 -> 2077.4668 | IN6: =IK6+IM6 -> 4263.682 | IP6: =IJ6-IL6 -> 36239.6 | IQ6: =IP6*P6*O6 -> 108.74833 | IR6: 3.272404 | IS6: =IR6*I6 -> 2020.6113 | IT6: 3.585511 | IU6: =IT6*I6 -> 2213.9455 | IV6: =(IR6-IT6)*I6 -> -193.33418 | IX6: 46057 | IY6: 905880.5 | IZ6: =IY6*P6*O6 -> 2718.3797 | JA6: 914235.5 | JB6: =JA6*P6*O6 -> 2743.4515 | JC6: =IZ6+JB6 -> 5461.8312 | JE6: =IY6-JA6 -> -8355 | JF6: =JE6*P6*O6 -> -25.071808 | JG6: 20.65023 | JH6: =JG6*J6 -> 2741.1115 | JI6: 20.86451 | JJ6: =JI6*J6 -> 2769.5551 | JK6: =(JG6-JI6)*J6 -> -28.443527 | JM6: 46057 | JN6: 854086.4 | JO6: =JN6*P6*O6 -> 2562.9552 | JP6: 868024.2 | JQ6: =JP6*P6*O6 -> 2604.7799 | JR6: =JO6+JQ6 -> 5167.7351 | JT6: =JN6-JP6 -> -13937.8 | JU6: =JT6*P6*O6 -> -41.824758 | JV6: 19.61083 | JW6: =JV6*J6 -> 2603.1416 | JX6: 19.68791 | JY6: =JX6*J6 -> 2613.3732 | JZ6: =(JV6-JX6)*J6 -> -10.231599 | KB6: 46057 | KC6: 869556.97 | KD6: =KC6*P6*O6 -> 2609.3795 | KE6: 895501.27 | KF6: =KE6*P6*O6 -> 2687.2335 | KG6: =KD6+KF6 -> 5296.613 | KI6: =KC6-KE6 -> -25944.299 | KJ6: =KI6*P6*O6 -> -77.854037 | KK6: 3.8110299 | KL6: =KK6*K6 -> 2632.3164 | KM6: 3.7810612 | KN6: =KM6*K6 -> 2611.6168 | KO6: =(KK6-KM6)*K6 -> 20.699648 | KQ6: 46057 | KR6: 858870.94 | KS6: =KR6*P6*O6 -> 2577.3127 | KT6: 881651.87 | KU6: =KT6*P6*O6 -> 2645.674 | KV6: =KS6+KU6 -> 5222.9867 | KX6: =KR6-KT6 -> -22780.922 | KY6: =KX6*P6*O6 -> -68.36133 | KZ6: 3.7536268 | LA6: =KZ6*K6 -> 2592.6675 | LB6: 3.7383382 | LC6: =LB6*K6 -> 2582.1076 | LD6: =(KZ6-LB6)*K6 -> 10.559944 | LF6: 46057 | LG6: 863593.78 | LH6: =LG6*P6*O6 -> 2591.4851 | LI6: 880610.16 | LJ6: =LI6*P6*O6 -> 2642.5481 | LK6: =LH6+LJ6 -> 5234.0331 | LM6: =LG6-LI6 -> -17016.385 | LN6: =LM6*P6*O6 -> -51.06302 | LO6: 46.634478 | LP6: =LO6*L6 -> 2608.2664 | LQ6: 46.67935 | LR6: =LQ6*L6 -> 2610.776 | LS6: =(LO6-LQ6)*L6 -> -2.5096742 | LU6: 46057 | LV6: 876875.78 | LW6: =LV6*P6*O6 -> 2631.3419 | LX6: 881756.19 | LY6: =LX6*P6*O6 -> 2645.9871 | LZ6: =LW6+LY6 -> 5277.329 | MB6: =LV6-LX6 -> -4880.4104 | MC6: =MB6*P6*O6 -> -14.645208 | MD6: 46.602966 | ME6: =MD6*L6 -> 2606.5039 | MF6: 47.388567 | MG6: =MF6*L6 -> 2650.4426 | MH6: =(MD6-MF6)*L6 -> -43.938704 | MJ6: 46057 | MK6: 853222.2 | ML6: =MK6*P6*O6 -> 2560.3619 | MM6: 863556.2 | MN6: =MM6*P6*O6 -> 2591.3723 | MO6: =ML6+MN6 -> 5151.7342 | MQ6: =MK6-MM6 -> -10334 | MR6: =MQ6*P6*O6 -> -31.010421 | MS6: 7.424228 | MT6: =MS6*M6 -> 2554.9738 | MU6: 7.48579 | MV6: =MU6*M6 -> 2576.1598 | MW6: =(MS6-MU6)*M6 -> -21.185947 | MY6: 46057 | MZ6: 840885.5 | NA6: =MZ6*P6*O6 -> 2523.3417 | NB6: 854779.2 | NC6: =NB6*P6*O6 -> 2565.0341 | ND6: =NA6+NC6 -> 5088.3759 | NF6: =MZ6-NB6 -> -13893.7 | NG6: =NF6*P6*O6 -> -41.692422 | NH6: 7.347979 | NI6: =NH6*M6 -> 2528.7335 | NJ6: 7.381757 | NK6: =NJ6*M6 -> 2540.3579 | NL6: =(NH6-NJ6)*M6 -> -11.624361 | NN6: 46057 | NO6: 828278 | NP6: =NO6*P6*O6 -> 2485.5089 | NQ6: 841706.1 | NR6: =NQ6*P6*O6 -> 2525.8042 | NS6: =NP6+NR6 -> 5011.3131 | NU6: =NO6-NQ6 -> -13428.1 | NV6: =NU6*P6*O6 -> -40.295242 | NW6: 325438.7 | NX6: =NW6*N6 -> 2463.571 | NY6: 333674.4 | NZ6: =NY6*N6 -> 2525.9152 | OA6: =(NW6-NY6)*N6 -> -62.344249 | OC6: 46057 | OD6: 839636.2 | OE6: =OD6*P6*O6 -> 2519.5928 | OF6: 848845.4 | OG6: =OF6*P6*O6 -> 2547.2279 | OH6: =OE6+OG6 -> 5066.8207 | OJ6: =OD6-OF6 -> -9209.2029 | OK6: =OJ6*P6*O6 -> -27.635113 | OL6: 328026.4 | OM6: =OL6*N6 -> 2483.1598 | ON6: 338271.9 | OO6: =ON6*N6 -> 2560.7183 | OP6: =(OL6-ON6)*N6 -> -77.558435
